Workbook

Sheet Paramètres
A1: PARAMÈTRES — Prévisions élevage de silure
A2: Cellules en bleu sur fond jaune = valeurs à modifier par vous. Le reste se calcule automatiquement.
A4: VENTE
A5: Prix de vente moyen (FCFA / kg) | B5: 1900
A6: Poids moyen d'un poisson à la vente (kg) | B6: 0.4 | C6: Sortie à 400 g en moyenne (les plus gros jusqu'à 600 g).
A7: Part du stock vendue à la fin du 2e mois du cycle | B7: 0 | C7: Mettre 0 % pour vendre la totalité au 3e mois ; augmenter si vous commencez à écouler dès la fin du 2e mois.
A8: Part vendue au cours du 3e mois (jusqu'à sa fin) | B8: =1-B7 -> 1 | C8: Calculé : 100 % − part du 2e mois. Ex. : vague d'août → la totalité vendue en octobre.
A10: ALEVINS
A11: Marge de sécurité sur les alevins (% ajouté à la commande) | B11: 0.1 | C11: On commande 10% d'alevins en plus pour couvrir le taux de perte.
A12: Prix d'un alevin (FCFA) | B12: 70 | C12: Prix D'EXEMPLE — mettez votre prix réel.
A14: REMISES FOURNISSEURS (négociées selon la taille des commandes)
A15: Remise obtenue sur les aliments et les alevins, selon la taille de la vague :
A16: Palier 1 — vague à partir de (t) / remise | B16: 0 | C16: 0 | D16: Remises D'EXEMPLE, à ajuster selon vos négociations réelles. Les seuils doivent rester en ordre croissant.
A17: Palier 2 — vague à partir de (t) / remise | B17: 5 | C17: 0.02
A18: Palier 3 — vague à partir de (t) / remise | B18: 10 | C18: 0.04
A19: Palier 4 — vague à partir de (t) / remise | B19: 15 | C19: 0.06
A21: ALIMENTS
A22: Kg d'aliment par kg de poisson — info, découle du standard de sacs | B22: =Aliments!$D$11/1000 -> 1.14 | C22: Le standard de sacs par tonne, les marques, prix et répartition se règlent dans la feuille Aliments.
A24: LOGISTIQUE — transport au voyage
A25: Capacité d'un voyage — aliments (sacs) | B25: 60 | C25: Nombre de sacs transportés par rotation.
A26: Coût d'un voyage — aliments (FCFA) | B26: 15000 | C26: Carburant + chauffeur + manutention, aller-retour.
A27: Capacité d'un voyage — poissons (kg) | B27: 1500 | C27: Charge utile par livraison de poisson vivant/frais.
A28: Coût d'un voyage — poissons (FCFA) | B28: 25000 | C28: Transport isotherme / glace incluse le cas échéant.
A29: Capacité d'un voyage — alevins (nb) | B29: 20000 | C29: Alevins transportés par rotation depuis l'écloserie.
A30: Coût d'un voyage — alevins (FCFA) | B30: 30000 | C30: Trajet écloserie → ferme.
A32: AUTRES DÉPENSES
A33: Saisie dans la feuille Dépenses (charges d'exploitation et charges ponctuelles). Le total remonte automatiquement dans les Prévisions. | C33: La logistique, elle, se calcule toute seule à partir des tarifs au voyage ci-dessus.
A35: FINANCES
A36: Part du résultat mensuel mise en épargne | B36: 0.3
A37: Trésorerie de départ en août 2026 (FCFA) | B37: 0
A39: INDICATEURS (calculés automatiquement)
A40: Coût aliment par kg de poisson produit (FCFA, sans remise) | B40: =Aliments!$D$13 -> 1216
A41: Coût alevins par kg vendu (FCFA, sans remise) | B41: =IF(B6=0,0,B12*(1+B11)/B6) -> 192.5
A42: Coût de production hors autres dépenses (FCFA / kg, sans remise) | B42: =B40+B41 -> 1408.5
A43: Idem pour une vague de 15 t, remise incluse (FCFA / kg) | B43: =B42*(1-INDEX($C$16:$C$19,MATCH(15,$B$16:$B$19,1))) -> 1323.99
A44: Marge brute d'une vague de 15 t, remise incluse (FCFA) | B44: =15000*(B5-B43) -> 8640150 | C44: Hors « autres dépenses », qui sont saisies mois par mois dans les Prévisions.
A45: Poissons à vendre dans une vague de 15 tonnes (nb) | B45: =IF(B6=0,0,15000/B6) -> 37500
A46: Alevins à commander pour une vague de 15 tonnes (nb) | B46: =B45*(1+B11) -> 41250

Sheet Aliments
A1: ALIMENTS — granulométries, marques, prix et répartition sur le cycle
A2: Grossissement du 2 mm au 4 mm (sortie à 400 g). Colonne « Sacs par tonne » : votre STANDARD de consommation pour produire 1 tonne de poisson (ex. 8 sacs de 2 mm, 18 de 3 mm, 50 de 4 mm) — c'est lui qui calcule les sacs de chaque vague selon son tonnage. Colonnes F, G, H : répartition de CHAQUE granulé sur les mois du cycle (chaque ligne doit faire 100%). Marques, poids et prix D'EXEMPLE à remplacer par vos valeurs réelles.
A3: Granulométrie | B3: Marque | C3: Poids du sac (kg) | D3: Prix du sac (FCFA) | E3: Prix au kg (FCFA) | F3: % consommé au mois 1 du cycle | G3: % consommé au mois 2 | H3: % consommé au mois 3 | I3: Total (doit faire 100%) | J3: Sacs par tonne de poisson (STANDARD) | K3: Contrôle
A4: 2 mm | B4: Marque A | C4: 15 | D4: 18000 | E4: =IF(N(C4)=0,0,D4/C4) -> 1200 | F4: 0.8 | G4: 0.2 | I4: =SUM(F4:H4) -> 1 | J4: 8 | K4: =IF(N(J4)=0,"",IF(ABS(I4-1)<0.001,"OK","≠ 100%")) -> OK
A5: 3 mm | B5: Marque A | C5: 15 | D5: 16500 | E5: =IF(N(C5)=0,0,D5/C5) -> 1100 | F5: 0.2 | G5: 0.8 | I5: =SUM(F5:H5) -> 1 | J5: 18 | K5: =IF(N(J5)=0,"",IF(ABS(I5-1)<0.001,"OK","≠ 100%")) -> OK
A6: 4 mm | B6: Marque B | C6: 15 | D6: 15500 | E6: =IF(N(C6)=0,0,D6/C6) -> 1033.3333 | G6: 0.4 | H6: 0.6 | I6: =SUM(F6:H6) -> 1 | J6: 50 | K6: =IF(N(J6)=0,"",IF(ABS(I6-1)<0.001,"OK","≠ 100%")) -> OK
E7: =IF(N(C7)=0,0,D7/C7) -> 0 | I7: =SUM(F7:H7) -> 0 | K7: =IF(N(J7)=0,"",IF(ABS(I7-1)<0.001,"OK","≠ 100%"))
E8: =IF(N(C8)=0,0,D8/C8) -> 0 | I8: =SUM(F8:H8) -> 0 | K8: =IF(N(J8)=0,"",IF(ABS(I8-1)<0.001,"OK","≠ 100%"))
E9: =IF(N(C9)=0,0,D9/C9) -> 0 | I9: =SUM(F9:H9) -> 0 | K9: =IF(N(J9)=0,"",IF(ABS(I9-1)<0.001,"OK","≠ 100%"))
A11: Aliment total par tonne de poisson (kg) — info | D11: =SUMPRODUCT($J$4:$J$9,$C$4:$C$9) -> 1140
A12: Coût aliment par tonne de poisson (FCFA, prix catalogue) | D12: =SUMPRODUCT($J$4:$J$9,$D$4:$D$9) -> 1216000
A13: Coût aliment par kg de poisson (FCFA, prix catalogue) | D13: =D12/1000 -> 1216 | E13: À comparer à votre expérience — remplacez marques, poids et prix d'exemple par vos valeurs réelles.

Sheet Empoissonnement
A1: PLAN D'EMPOISSONNEMENT — une ligne par vague
A2: Colonnes en bleu à modifier : C (tonnage visé) et F (alevins achetés ? OUI/NON — NON = alevins issus de votre production locale, coût nul). Le plan démarre en août 2026 (V1) et se termine en février 2028 (V19) ; les ventes du dernier cycle vont jusqu'en avril 2028.
A3: Vague | B3: Mois d'empoissonnement | C3: Objectif de vente (t) | D3: Poissons à vendre (nb approx.) | E3: Alevins à commander (nb, marge de sécurité incluse) | F3: Alevins achetés ? (OUI/NON) | G3: Remise fournisseur (%) | H3: Coût alevins (FCFA) | I3: Coût aliments de la vague (FCFA) | J3: Coût total aliments + alevins (FCFA) | K3: Coût de production partiel (FCFA/kg — aliments + alevins seuls) | L3: Chiffre d'affaires attendu (FCFA) | M3: Marge brute attendue (FCFA) | N3: Dépenses affectées à la vague (FCFA) | O3: Quote-part charges générales (FCFA) | P3: Coût complet de la vague (FCFA) | Q3: COÛT DE PRODUCTION COMPLET (FCFA/kg) | R3: Marge nette attendue (FCFA)
A4: V1 | B4: 46235 | C4: 4 | D4: =IF(Paramètres!$B$6=0,0,ROUND(C4*1000/Paramètres!$B$6,0)) -> 10000 | E4: =ROUNDUP(D4*(1+Paramètres!$B$11),0) -> 11000 | F4: NON | G4: =INDEX(Paramètres!$C$16:$C$19,MATCH(C4,Paramètres!$B$16:$B$19,1)) -> 0 | H4: =IF($F4="NON",0,E4*Paramètres!$B$12*(1-G4)) -> 0 | I4: ='Aliment par vague'!$L4 -> 4864000 | J4: =H4+I4 -> 4864000 | K4: =IF(C4=0,0,J4/(C4*1000)) -> 1216 | L4: =C4*1000*Paramètres!$B$5 -> 7600000 | M4: =L4-J4 -> 2736000 | N4: =SUMIFS(Journal[Montant],Journal[Vague],$A4,Journal[Catégorie],"Opérationnel") -> 0 | O4: ='Aliment par vague'!$W4 -> 2252740.1 | P4: =J4+N4+O4 -> 7116740.1 | Q4: =IF(C4=0,0,P4/(C4*1000)) -> 1779.185 | R4: =L4-P4 -> 483259.86
A5: V2 | B5: 46266 | C5: 4 | D5: =IF(Paramètres!$B$6=0,0,ROUND(C5*1000/Paramètres!$B$6,0)) -> 10000 | E5: =ROUNDUP(D5*(1+Paramètres!$B$11),0) -> 11000 | F5: NON | G5: =INDEX(Paramètres!$C$16:$C$19,MATCH(C5,Paramètres!$B$16:$B$19,1)) -> 0 | H5: =IF($F5="NON",0,E5*Paramètres!$B$12*(1-G5)) -> 0 | I5: ='Aliment par vague'!$L5 -> 4864000 | J5: =H5+I5 -> 4864000 | K5: =IF(C5=0,0,J5/(C5*1000)) -> 1216 | L5: =C5*1000*Paramètres!$B$5 -> 7600000 | M5: =L5-J5 -> 2736000 | N5: =SUMIFS(Journal[Montant],Journal[Vague],$A5,Journal[Catégorie],"Opérationnel") -> 0 | O5: ='Aliment par vague'!$W5 -> 1044404.3 | P5: =J5+N5+O5 -> 5908404.3 | Q5: =IF(C5=0,0,P5/(C5*1000)) -> 1477.1011 | R5: =L5-P5 -> 1691595.7
A6: V3 | B6: 46296 | C6: 8 | D6: =IF(Paramètres!$B$6=0,0,ROUND(C6*1000/Paramètres!$B$6,0)) -> 20000 | E6: =ROUNDUP(D6*(1+Paramètres!$B$11),0) -> 22000 | F6: NON | G6: =INDEX(Paramètres!$C$16:$C$19,MATCH(C6,Paramètres!$B$16:$B$19,1)) -> 0.02 | H6: =IF($F6="NON",0,E6*Paramètres!$B$12*(1-G6)) -> 0 | I6: ='Aliment par vague'!$L6 -> 9533440 | J6: =H6+I6 -> 9533440 | K6: =IF(C6=0,0,J6/(C6*1000)) -> 1191.68 | L6: =C6*1000*Paramètres!$B$5 -> 15200000 | M6: =L6-J6 -> 5666560 | N6: =SUMIFS(Journal[Montant],Journal[Vague],$A6,Journal[Catégorie],"Opérationnel") -> 0 | O6: ='Aliment par vague'!$W6 -> 1535771.9 | P6: =J6+N6+O6 -> 11069212 | Q6: =IF(C6=0,0,P6/(C6*1000)) -> 1383.6515 | R6: =L6-P6 -> 4130788.1
A7: V4 | B7: 46327 | C7: 8 | D7: =IF(Paramètres!$B$6=0,0,ROUND(C7*1000/Paramètres!$B$6,0)) -> 20000 | E7: =ROUNDUP(D7*(1+Paramètres!$B$11),0) -> 22000 | F7: NON | G7: =INDEX(Paramètres!$C$16:$C$19,MATCH(C7,Paramètres!$B$16:$B$19,1)) -> 0.02 | H7: =IF($F7="NON",0,E7*Paramètres!$B$12*(1-G7)) -> 0 | I7: ='Aliment par vague'!$L7 -> 9533440 | J7: =H7+I7 -> 9533440 | K7: =IF(C7=0,0,J7/(C7*1000)) -> 1191.68 | L7: =C7*1000*Paramètres!$B$5 -> 15200000 | M7: =L7-J7 -> 5666560 | N7: =SUMIFS(Journal[Montant],Journal[Vague],$A7,Journal[Catégorie],"Opérationnel") -> 0 | O7: ='Aliment par vague'!$W7 -> 1287986 | P7: =J7+N7+O7 -> 10821426 | Q7: =IF(C7=0,0,P7/(C7*1000)) -> 1352.6782 | R7: =L7-P7 -> 4378574
A8: V5 | B8: 46357 | C8: 10 | D8: =IF(Paramètres!$B$6=0,0,ROUND(C8*1000/Paramètres!$B$6,0)) -> 25000 | E8: =ROUNDUP(D8*(1+Paramètres!$B$11),0) -> 27500 | F8: NON | G8: =INDEX(Paramètres!$C$16:$C$19,MATCH(C8,Paramètres!$B$16:$B$19,1)) -> 0.04 | H8: =IF($F8="NON",0,E8*Paramètres!$B$12*(1-G8)) -> 0 | I8: ='Aliment par vague'!$L8 -> 11673600 | J8: =H8+I8 -> 11673600 | K8: =IF(C8=0,0,J8/(C8*1000)) -> 1167.36 | L8: =C8*1000*Paramètres!$B$5 -> 19000000 | M8: =L8-J8 -> 7326400 | N8: =SUMIFS(Journal[Montant],Journal[Vague],$A8,Journal[Catégorie],"Opérationnel") -> 0 | O8: ='Aliment par vague'!$W8 -> 1408264.3 | P8: =J8+N8+O8 -> 13081864 | Q8: =IF(C8=0,0,P8/(C8*1000)) -> 1308.1864 | R8: =L8-P8 -> 5918135.7
A9: V6 | B9: 46388 | C9: 12 | D9: =IF(Paramètres!$B$6=0,0,ROUND(C9*1000/Paramètres!$B$6,0)) -> 30000 | E9: =ROUNDUP(D9*(1+Paramètres!$B$11),0) -> 33000 | F9: NON | G9: =INDEX(Paramètres!$C$16:$C$19,MATCH(C9,Paramètres!$B$16:$B$19,1)) -> 0.04 | H9: =IF($F9="NON",0,E9*Paramètres!$B$12*(1-G9)) -> 0 | I9: ='Aliment par vague'!$L9 -> 14008320 | J9: =H9+I9 -> 14008320 | K9: =IF(C9=0,0,J9/(C9*1000)) -> 1167.36 | L9: =C9*1000*Paramètres!$B$5 -> 22800000 | M9: =L9-J9 -> 8791680 | N9: =SUMIFS(Journal[Montant],Journal[Vague],$A9,Journal[Catégorie],"Opérationnel") -> 0 | O9: ='Aliment par vague'!$W9 -> 1478833.3 | P9: =J9+N9+O9 -> 15487153 | Q9: =IF(C9=0,0,P9/(C9*1000)) -> 1290.5961 | R9: =L9-P9 -> 7312846.7
A10: V7 | B10: 46419 | C10: 15 | D10: =IF(Paramètres!$B$6=0,0,ROUND(C10*1000/Paramètres!$B$6,0)) -> 37500 | E10: =ROUNDUP(D10*(1+Paramètres!$B$11),0) -> 41250 | F10: NON | G10: =INDEX(Paramètres!$C$16:$C$19,MATCH(C10,Paramètres!$B$16:$B$19,1)) -> 0.06 | H10: =IF($F10="NON",0,E10*Paramètres!$B$12*(1-G10)) -> 0 | I10: ='Aliment par vague'!$L10 -> 17145600 | J10: =H10+I10 -> 17145600 | K10: =IF(C10=0,0,J10/(C10*1000)) -> 1143.04 | L10: =C10*1000*Paramètres!$B$5 -> 28500000 | M10: =L10-J10 -> 11354400 | N10: =SUMIFS(Journal[Montant],Journal[Vague],$A10,Journal[Catégorie],"Opérationnel") -> 0 | O10: ='Aliment par vague'!$W10 -> 1675552.6 | P10: =J10+N10+O10 -> 18821153 | Q10: =IF(C10=0,0,P10/(C10*1000)) -> 1254.7435 | R10: =L10-P10 -> 9678847.4
A11: V8 | B11: 46447 | C11: 15 | D11: =IF(Paramètres!$B$6=0,0,ROUND(C11*1000/Paramètres!$B$6,0)) -> 37500 | E11: =ROUNDUP(D11*(1+Paramètres!$B$11),0) -> 41250 | F11: NON | G11: =INDEX(Paramètres!$C$16:$C$19,MATCH(C11,Paramètres!$B$16:$B$19,1)) -> 0.06 | H11: =IF($F11="NON",0,E11*Paramètres!$B$12*(1-G11)) -> 0 | I11: ='Aliment par vague'!$L11 -> 17145600 | J11: =H11+I11 -> 17145600 | K11: =IF(C11=0,0,J11/(C11*1000)) -> 1143.04 | L11: =C11*1000*Paramètres!$B$5 -> 28500000 | M11: =L11-J11 -> 11354400 | N11: =SUMIFS(Journal[Montant],Journal[Vague],$A11,Journal[Catégorie],"Opérationnel") -> 0 | O11: ='Aliment par vague'!$W11 -> 1613815.8 | P11: =J11+N11+O11 -> 18759416 | Q11: =IF(C11=0,0,P11/(C11*1000)) -> 1250.6277 | R11: =L11-P11 -> 9740584.2
A12: V9 | B12: 46478 | C12: 15 | D12: =IF(Paramètres!$B$6=0,0,ROUND(C12*1000/Paramètres!$B$6,0)) -> 37500 | E12: =ROUNDUP(D12*(1+Paramètres!$B$11),0) -> 41250 | F12: NON | G12: =INDEX(Paramètres!$C$16:$C$19,MATCH(C12,Paramètres!$B$16:$B$19,1)) -> 0.06 | H12: =IF($F12="NON",0,E12*Paramètres!$B$12*(1-G12)) -> 0 | I12: ='Aliment par vague'!$L12 -> 17145600 | J12: =H12+I12 -> 17145600 | K12: =IF(C12=0,0,J12/(C12*1000)) -> 1143.04 | L12: =C12*1000*Paramètres!$B$5 -> 28500000 | M12: =L12-J12 -> 11354400 | N12: =SUMIFS(Journal[Montant],Journal[Vague],$A12,Journal[Catégorie],"Opérationnel") -> 0 | O12: ='Aliment par vague'!$W12 -> 1605000 | P12: =J12+N12+O12 -> 18750600 | Q12: =IF(C12=0,0,P12/(C12*1000)) -> 1250.04 | R12: =L12-P12 -> 9749400
A13: V10 | B13: 46508 | C13: 15 | D13: =IF(Paramètres!$B$6=0,0,ROUND(C13*1000/Paramètres!$B$6,0)) -> 37500 | E13: =ROUNDUP(D13*(1+Paramètres!$B$11),0) -> 41250 | F13: NON | G13: =INDEX(Paramètres!$C$16:$C$19,MATCH(C13,Paramètres!$B$16:$B$19,1)) -> 0.06 | H13: =IF($F13="NON",0,E13*Paramètres!$B$12*(1-G13)) -> 0 | I13: ='Aliment par vague'!$L13 -> 17145600 | J13: =H13+I13 -> 17145600 | K13: =IF(C13=0,0,J13/(C13*1000)) -> 1143.04 | L13: =C13*1000*Paramètres!$B$5 -> 28500000 | M13: =L13-J13 -> 11354400 | N13: =SUMIFS(Journal[Montant],Journal[Vague],$A13,Journal[Catégorie],"Opérationnel") -> 0 | O13: ='Aliment par vague'!$W13 -> 1605000 | P13: =J13+N13+O13 -> 18750600 | Q13: =IF(C13=0,0,P13/(C13*1000)) -> 1250.04 | R13: =L13-P13 -> 9749400
A14: V11 | B14: 46539 | C14: 15 | D14: =IF(Paramètres!$B$6=0,0,ROUND(C14*1000/Paramètres!$B$6,0)) -> 37500 | E14: =ROUNDUP(D14*(1+Paramètres!$B$11),0) -> 41250 | F14: NON | G14: =INDEX(Paramètres!$C$16:$C$19,MATCH(C14,Paramètres!$B$16:$B$19,1)) -> 0.06 | H14: =IF($F14="NON",0,E14*Paramètres!$B$12*(1-G14)) -> 0 | I14: ='Aliment par vague'!$L14 -> 17145600 | J14: =H14+I14 -> 17145600 | K14: =IF(C14=0,0,J14/(C14*1000)) -> 1143.04 | L14: =C14*1000*Paramètres!$B$5 -> 28500000 | M14: =L14-J14 -> 11354400 | N14: =SUMIFS(Journal[Montant],Journal[Vague],$A14,Journal[Catégorie],"Opérationnel") -> 0 | O14: ='Aliment par vague'!$W14 -> 1605000 | P14: =J14+N14+O14 -> 18750600 | Q14: =IF(C14=0,0,P14/(C14*1000)) -> 1250.04 | R14: =L14-P14 -> 9749400
A15: V12 | B15: 46569 | C15: 15 | D15: =IF(Paramètres!$B$6=0,0,ROUND(C15*1000/Paramètres!$B$6,0)) -> 37500 | E15: =ROUNDUP(D15*(1+Paramètres!$B$11),0) -> 41250 | F15: NON | G15: =INDEX(Paramètres!$C$16:$C$19,MATCH(C15,Paramètres!$B$16:$B$19,1)) -> 0.06 | H15: =IF($F15="NON",0,E15*Paramètres!$B$12*(1-G15)) -> 0 | I15: ='Aliment par vague'!$L15 -> 17145600 | J15: =H15+I15 -> 17145600 | K15: =IF(C15=0,0,J15/(C15*1000)) -> 1143.04 | L15: =C15*1000*Paramètres!$B$5 -> 28500000 | M15: =L15-J15 -> 11354400 | N15: =SUMIFS(Journal[Montant],Journal[Vague],$A15,Journal[Catégorie],"Opérationnel") -> 0 | O15: ='Aliment par vague'!$W15 -> 1605000 | P15: =J15+N15+O15 -> 18750600 | Q15: =IF(C15=0,0,P15/(C15*1000)) -> 1250.04 | R15: =L15-P15 -> 9749400
... A22: V19 | B22: 46784 | C22: 15 | D22: =IF(Paramètres!$B$6=0,0,ROUND(C22*1000/Paramètres!$B$6,0)) -> 37500 | E22: =ROUNDUP(D22*(1+Paramètres!$B$11),0) -> 41250 | F22: NON | G22: =INDEX(Paramètres!$C$16:$C$19,MATCH(C22,Paramètres!$B$16:$B$19,1)) -> 0.06 | H22: =IF($F22="NON",0,E22*Paramètres!$B$12*(1-G22)) -> 0 | I22: ='Aliment par vague'!$L22 -> 17145600 | J22: =H22+I22 -> 17145600 | K22: =IF(C22=0,0,J22/(C22*1000)) -> 1143.04 | L22: =C22*1000*Paramètres!$B$5 -> 28500000 | M22: =L22-J22 -> 11354400 | N22: =SUMIFS(Journal[Montant],Journal[Vague],$A22,Journal[Catégorie],"Opérationnel") -> 0 | O22: ='Aliment par vague'!$W22 -> 2371184.2 | P22: =J22+N22+O22 -> 19516784 | Q22: =IF(C22=0,0,P22/(C22*1000)) -> 1301.1189 | R22: =L22-P22 -> 8983215.8
A23: TOTAL | C23: =SUM(C4:C22) -> 241 | D23: =SUM(D4:D22) -> 602500 | E23: =SUM(E4:E22) -> 662750 | H23: =SUM(H4:H22) -> 0 | I23: =SUM(I4:I22) -> 277369600 | J23: =SUM(J4:J22) -> 277369600 | K23: =IF(C23=0,0,J23/(C23*1000)) -> 1150.9112 | L23: =SUM(L4:L22) -> 457900000 | M23: =SUM(M4:M22) -> 180530400 | N23: =SUM(N4:N22) -> 0 | O23: =SUM(O4:O22) -> 30760000 | P23: =SUM(P4:P22) -> 308129600 | Q23: =IF(C23=0,0,P23/(C23*1000)) -> 1278.5461 | R23: =SUM(R4:R22) -> 149770400

Sheet Aliment par vague
A1: ALIMENT PAR VAGUE — saisissez les SACS de chaque vague, par granulométrie
A2: Les sacs de chaque vague sont CALCULÉS depuis son tonnage (Empoissonnement) × le standard « sacs par tonne » de la feuille Aliments. Pour une vague particulière, vous pouvez taper un nombre de sacs par-dessus la formule. Kilos et coûts (remise fournisseur déduite) se calculent tout seuls ; la répartition de chaque granulé entre les mois du cycle suit la feuille Aliments.
A3: Vague | B3: Mois d'empoissonnement | C3: Objectif (t) | D3: =IF(Aliments!$A$4="","—",Aliments!$A$4&" (sacs)") -> 2 mm (sacs) | E3: =IF(Aliments!$A$5="","—",Aliments!$A$5&" (sacs)") -> 3 mm (sacs) | F3: =IF(Aliments!$A$6="","—",Aliments!$A$6&" (sacs)") -> 4 mm (sacs) | G3: =IF(Aliments!$A$7="","—",Aliments!$A$7&" (sacs)") -> — | H3: =IF(Aliments!$A$8="","—",Aliments!$A$8&" (sacs)") -> — | I3: =IF(Aliments!$A$9="","—",Aliments!$A$9&" (sacs)") -> — | J3: Total sacs | K3: Total kg | L3: Coût total aliments (FCFA, remise déduite) | Q3: Aliment mois 1 (kg) | R3: Aliment mois 2 (kg) | S3: Aliment mois 3 (kg) | T3: Quote-part charges mois 1 (FCFA) | U3: Quote-part charges mois 2 (FCFA) | V3: Quote-part charges mois 3 (FCFA) | W3: Quote-part charges générales — total (FCFA)
A4: =Empoissonnement!A4 -> V1 | B4: =Empoissonnement!B4 -> 46235 | C4: =Empoissonnement!C4 -> 4 | D4: =ROUNDUP(Empoissonnement!C4*N(Aliments!$J$4),0) -> 32 | E4: =ROUNDUP(Empoissonnement!C4*N(Aliments!$J$5),0) -> 72 | F4: =ROUNDUP(Empoissonnement!C4*N(Aliments!$J$6),0) -> 200 | G4: =ROUNDUP(Empoissonnement!C4*N(Aliments!$J$7),0) -> 0 | H4: =ROUNDUP(Empoissonnement!C4*N(Aliments!$J$8),0) -> 0 | I4: =ROUNDUP(Empoissonnement!C4*N(Aliments!$J$9),0) -> 0 | J4: =SUM(D4:I4) -> 304 | K4: =D4*N(Aliments!$C$4)+E4*N(Aliments!$C$5)+F4*N(Aliments!$C$6)+G4*N(Aliments!$C$7)+H4*N(Aliments!$C$8)+I4*N(Aliments!$C$9) -> 4560 | L4: =(D4*N(Aliments!$D$4)+E4*N(Aliments!$D$5)+F4*N(Aliments!$D$6)+G4*N(Aliments!$D$7)+H4*N(Aliments!$D$8)+I4*N(Aliments!$D$9))*(1-Empoissonnement!$G4) -> 4864000 | N4: =(D4*N(Aliments!$D$4)*N(Aliments!$F$4)+E4*N(Aliments!$D$5)*N(Aliments!$F$5)+F4*N(Aliments!$D$6)*N(Aliments!$F$6)+G4*N(Aliments!$D$7)*N(Aliments!$F$7)+H4*N(Aliments!$D$8)*N(Aliments!$F$8)+I4*N(Aliments!$D$9)*N(Aliments!$F$9))*(1-Empoissonnement!$G4) -> 698400 | O4: =(D4*N(Aliments!$D$4)*N(Aliments!$G$4)+E4*N(Aliments!$D$5)*N(Aliments!$G$5)+F4*N(Aliments!$D$6)*N(Aliments!$G$6)+G4*N(Aliments!$D$7)*N(Aliments!$G$7)+H4*N(Aliments!$D$8)*N(Aliments!$G$8)+I4*N(Aliments!$D$9)*N(Aliments!$G$9))*(1-Empoissonnement!$G4) -> 2305600 | P4: =(D4*N(Aliments!$D$4)*N(Aliments!$H$4)+E4*N(Aliments!$D$5)*N(Aliments!$H$5)+F4*N(Aliments!$D$6)*N(Aliments!$H$6)+G4*N(Aliments!$D$7)*N(Aliments!$H$7)+H4*N(Aliments!$D$8)*N(Aliments!$H$8)+I4*N(Aliments!$D$9)*N(Aliments!$H$9))*(1-Empoissonnement!$G4) -> 1860000 | Q4: =D4*N(Aliments!$C$4)*N(Aliments!$F$4)+E4*N(Aliments!$C$5)*N(Aliments!$F$5)+F4*N(Aliments!$C$6)*N(Aliments!$F$6)+G4*N(Aliments!$C$7)*N(Aliments!$F$7)+H4*N(Aliments!$C$8)*N(Aliments!$F$8)+I4*N(Aliments!$C$9)*N(Aliments!$F$9) -> 600 | R4: =D4*N(Aliments!$C$4)*N(Aliments!$G$4)+E4*N(Aliments!$C$5)*N(Aliments!$G$5)+F4*N(Aliments!$C$6)*N(Aliments!$G$6)+G4*N(Aliments!$C$7)*N(Aliments!$G$7)+H4*N(Aliments!$C$8)*N(Aliments!$G$8)+I4*N(Aliments!$C$9)*N(Aliments!$G$9) -> 2160 | S4: =D4*N(Aliments!$C$4)*N(Aliments!$H$4)+E4*N(Aliments!$C$5)*N(Aliments!$H$5)+F4*N(Aliments!$C$6)*N(Aliments!$H$6)+G4*N(Aliments!$C$7)*N(Aliments!$H$7)+H4*N(Aliments!$C$8)*N(Aliments!$H$8)+I4*N(Aliments!$C$9)*N(Aliments!$H$9) -> 1800 | T4: =IFERROR(Q4/INDEX('Besoins aliments'!$H$5:$H$25,MATCH(Empoissonnement!$B4,'Besoins aliments'!$A$5:$A$25,0))*INDEX(Dépenses!$B$31:$V$31,MATCH(Empoissonnement!$B4,Dépenses!$B$3:$V$3,0)),0) -> 995000 | U4: =IFERROR(R4/INDEX('Besoins aliments'!$H$5:$H$25,MATCH(EDATE(Empoissonnement!$B4,1),'Besoins aliments'!$A$5:$A$25,0))*INDEX(Dépenses!$B$31:$V$31,MATCH(EDATE(Empoissonnement!$B4,1),Dépenses!$B$3:$V$3,0)),0) -> 837391.3 | V4: =IFERROR(S4/INDEX('Besoins aliments'!$H$5:$H$25,MATCH(EDATE(Empoissonnement!$B4,2),'Besoins aliments'!$A$5:$A$25,0))*INDEX(Dépenses!$B$31:$V$31,MATCH(EDATE(Empoissonnement!$B4,2),Dépenses!$B$3:$V$3,0)),0) -> 420348.84 | W4: =T4+U4+V4 -> 2252740.1
A5: =Empoissonnement!A5 -> V2 | B5: =Empoissonnement!B5 -> 46266 | C5: =Empoissonnement!C5 -> 4 | D5: =ROUNDUP(Empoissonnement!C5*N(Aliments!$J$4),0) -> 32 | E5: =ROUNDUP(Empoissonnement!C5*N(Aliments!$J$5),0) -> 72 | F5: =ROUNDUP(Empoissonnement!C5*N(Aliments!$J$6),0) -> 200 | G5: =ROUNDUP(Empoissonnement!C5*N(Aliments!$J$7),0) -> 0 | H5: =ROUNDUP(Empoissonnement!C5*N(Aliments!$J$8),0) -> 0 | I5: =ROUNDUP(Empoissonnement!C5*N(Aliments!$J$9),0) -> 0 | J5: =SUM(D5:I5) -> 304 | K5: =D5*N(Aliments!$C$4)+E5*N(Aliments!$C$5)+F5*N(Aliments!$C$6)+G5*N(Aliments!$C$7)+H5*N(Aliments!$C$8)+I5*N(Aliments!$C$9) -> 4560 | L5: =(D5*N(Aliments!$D$4)+E5*N(Aliments!$D$5)+F5*N(Aliments!$D$6)+G5*N(Aliments!$D$7)+H5*N(Aliments!$D$8)+I5*N(Aliments!$D$9))*(1-Empoissonnement!$G5) -> 4864000 | N5: =(D5*N(Aliments!$D$4)*N(Aliments!$F$4)+E5*N(Aliments!$D$5)*N(Aliments!$F$5)+F5*N(Aliments!$D$6)*N(Aliments!$F$6)+G5*N(Aliments!$D$7)*N(Aliments!$F$7)+H5*N(Aliments!$D$8)*N(Aliments!$F$8)+I5*N(Aliments!$D$9)*N(Aliments!$F$9))*(1-Empoissonnement!$G5) -> 698400 | O5: =(D5*N(Aliments!$D$4)*N(Aliments!$G$4)+E5*N(Aliments!$D$5)*N(Aliments!$G$5)+F5*N(Aliments!$D$6)*N(Aliments!$G$6)+G5*N(Aliments!$D$7)*N(Aliments!$G$7)+H5*N(Aliments!$D$8)*N(Aliments!$G$8)+I5*N(Aliments!$D$9)*N(Aliments!$G$9))*(1-Empoissonnement!$G5) -> 2305600 | P5: =(D5*N(Aliments!$D$4)*N(Aliments!$H$4)+E5*N(Aliments!$D$5)*N(Aliments!$H$5)+F5*N(Aliments!$D$6)*N(Aliments!$H$6)+G5*N(Aliments!$D$7)*N(Aliments!$H$7)+H5*N(Aliments!$D$8)*N(Aliments!$H$8)+I5*N(Aliments!$D$9)*N(Aliments!$H$9))*(1-Empoissonnement!$G5) -> 1860000 | Q5: =D5*N(Aliments!$C$4)*N(Aliments!$F$4)+E5*N(Aliments!$C$5)*N(Aliments!$F$5)+F5*N(Aliments!$C$6)*N(Aliments!$F$6)+G5*N(Aliments!$C$7)*N(Aliments!$F$7)+H5*N(Aliments!$C$8)*N(Aliments!$F$8)+I5*N(Aliments!$C$9)*N(Aliments!$F$9) -> 600 | R5: =D5*N(Aliments!$C$4)*N(Aliments!$G$4)+E5*N(Aliments!$C$5)*N(Aliments!$G$5)+F5*N(Aliments!$C$6)*N(Aliments!$G$6)+G5*N(Aliments!$C$7)*N(Aliments!$G$7)+H5*N(Aliments!$C$8)*N(Aliments!$G$8)+I5*N(Aliments!$C$9)*N(Aliments!$G$9) -> 2160 | S5: =D5*N(Aliments!$C$4)*N(Aliments!$H$4)+E5*N(Aliments!$C$5)*N(Aliments!$H$5)+F5*N(Aliments!$C$6)*N(Aliments!$H$6)+G5*N(Aliments!$C$7)*N(Aliments!$H$7)+H5*N(Aliments!$C$8)*N(Aliments!$H$8)+I5*N(Aliments!$C$9)*N(Aliments!$H$9) -> 1800 | T5: =IFERROR(Q5/INDEX('Besoins aliments'!$H$5:$H$25,MATCH(Empoissonnement!$B5,'Besoins aliments'!$A$5:$A$25,0))*INDEX(Dépenses!$B$31:$V$31,MATCH(Empoissonnement!$B5,Dépenses!$B$3:$V$3,0)),0) -> 232608.7 | U5: =IFERROR(R5/INDEX('Besoins aliments'!$H$5:$H$25,MATCH(EDATE(Empoissonnement!$B5,1),'Besoins aliments'!$A$5:$A$25,0))*INDEX(Dépenses!$B$31:$V$31,MATCH(EDATE(Empoissonnement!$B5,1),Dépenses!$B$3:$V$3,0)),0) -> 504418.6 | V5: =IFERROR(S5/INDEX('Besoins aliments'!$H$5:$H$25,MATCH(EDATE(Empoissonnement!$B5,2),'Besoins aliments'!$A$5:$A$25,0))*INDEX(Dépenses!$B$31:$V$31,MATCH(EDATE(Empoissonnement!$B5,2),Dépenses!$B$3:$V$3,0)),0) -> 307377.05 | W5: =T5+U5+V5 -> 1044404.3
A6: =Empoissonnement!A6 -> V3 | B6: =Empoissonnement!B6 -> 46296 | C6: =Empoissonnement!C6 -> 8 | D6: =ROUNDUP(Empoissonnement!C6*N(Aliments!$J$4),0) -> 64 | E6: =ROUNDUP(Empoissonnement!C6*N(Aliments!$J$5),0) -> 144 | F6: =ROUNDUP(Empoissonnement!C6*N(Aliments!$J$6),0) -> 400 | G6: =ROUNDUP(Empoissonnement!C6*N(Aliments!$J$7),0) -> 0 | H6: =ROUNDUP(Empoissonnement!C6*N(Aliments!$J$8),0) -> 0 | I6: =ROUNDUP(Empoissonnement!C6*N(Aliments!$J$9),0) -> 0 | J6: =SUM(D6:I6) -> 608 | K6: =D6*N(Aliments!$C$4)+E6*N(Aliments!$C$5)+F6*N(Aliments!$C$6)+G6*N(Aliments!$C$7)+H6*N(Aliments!$C$8)+I6*N(Aliments!$C$9) -> 9120 | L6: =(D6*N(Aliments!$D$4)+E6*N(Aliments!$D$5)+F6*N(Aliments!$D$6)+G6*N(Aliments!$D$7)+H6*N(Aliments!$D$8)+I6*N(Aliments!$D$9))*(1-Empoissonnement!$G6) -> 9533440 | N6: =(D6*N(Aliments!$D$4)*N(Aliments!$F$4)+E6*N(Aliments!$D$5)*N(Aliments!$F$5)+F6*N(Aliments!$D$6)*N(Aliments!$F$6)+G6*N(Aliments!$D$7)*N(Aliments!$F$7)+H6*N(Aliments!$D$8)*N(Aliments!$F$8)+I6*N(Aliments!$D$9)*N(Aliments!$F$9))*(1-Empoissonnement!$G6) -> 1368864 | O6: =(D6*N(Aliments!$D$4)*N(Aliments!$G$4)+E6*N(Aliments!$D$5)*N(Aliments!$G$5)+F6*N(Aliments!$D$6)*N(Aliments!$G$6)+G6*N(Aliments!$D$7)*N(Aliments!$G$7)+H6*N(Aliments!$D$8)*N(Aliments!$G$8)+I6*N(Aliments!$D$9)*N(Aliments!$G$9))*(1-Empoissonnement!$G6) -> 4518976 | P6: =(D6*N(Aliments!$D$4)*N(Aliments!$H$4)+E6*N(Aliments!$D$5)*N(Aliments!$H$5)+F6*N(Aliments!$D$6)*N(Aliments!$H$6)+G6*N(Aliments!$D$7)*N(Aliments!$H$7)+H6*N(Aliments!$D$8)*N(Aliments!$H$8)+I6*N(Aliments!$D$9)*N(Aliments!$H$9))*(1-Empoissonnement!$G6) -> 3645600 | Q6: =D6*N(Aliments!$C$4)*N(Aliments!$F$4)+E6*N(Aliments!$C$5)*N(Aliments!$F$5)+F6*N(Aliments!$C$6)*N(Aliments!$F$6)+G6*N(Aliments!$C$7)*N(Aliments!$F$7)+H6*N(Aliments!$C$8)*N(Aliments!$F$8)+I6*N(Aliments!$C$9)*N(Aliments!$F$9) -> 1200 | R6: =D6*N(Aliments!$C$4)*N(Aliments!$G$4)+E6*N(Aliments!$C$5)*N(Aliments!$G$5)+F6*N(Aliments!$C$6)*N(Aliments!$G$6)+G6*N(Aliments!$C$7)*N(Aliments!$G$7)+H6*N(Aliments!$C$8)*N(Aliments!$G$8)+I6*N(Aliments!$C$9)*N(Aliments!$G$9) -> 4320 | S6: =D6*N(Aliments!$C$4)*N(Aliments!$H$4)+E6*N(Aliments!$C$5)*N(Aliments!$H$5)+F6*N(Aliments!$C$6)*N(Aliments!$H$6)+G6*N(Aliments!$C$7)*N(Aliments!$H$7)+H6*N(Aliments!$C$8)*N(Aliments!$H$8)+I6*N(Aliments!$C$9)*N(Aliments!$H$9) -> 3600 | T6: =IFERROR(Q6/INDEX('Besoins aliments'!$H$5:$H$25,MATCH(Empoissonnement!$B6,'Besoins aliments'!$A$5:$A$25,0))*INDEX(Dépenses!$B$31:$V$31,MATCH(Empoissonnement!$B6,Dépenses!$B$3:$V$3,0)),0) -> 280232.56 | U6: =IFERROR(R6/INDEX('Besoins aliments'!$H$5:$H$25,MATCH(EDATE(Empoissonnement!$B6,1),'Besoins aliments'!$A$5:$A$25,0))*INDEX(Dépenses!$B$31:$V$31,MATCH(EDATE(Empoissonnement!$B6,1),Dépenses!$B$3:$V$3,0)),0) -> 737704.92 | V6: =IFERROR(S6/INDEX('Besoins aliments'!$H$5:$H$25,MATCH(EDATE(Empoissonnement!$B6,2),'Besoins aliments'!$A$5:$A$25,0))*INDEX(Dépenses!$B$31:$V$31,MATCH(EDATE(Empoissonnement!$B6,2),Dépenses!$B$3:$V$3,0)),0) -> 517834.39 | W6: =T6+U6+V6 -> 1535771.9
A7: =Empoissonnement!A7 -> V4 | B7: =Empoissonnement!B7 -> 46327 | C7: =Empoissonnement!C7 -> 8 | D7: =ROUNDUP(Empoissonnement!C7*N(Aliments!$J$4),0) -> 64 | E7: =ROUNDUP(Empoissonnement!C7*N(Aliments!$J$5),0) -> 144 | F7: =ROUNDUP(Empoissonnement!C7*N(Aliments!$J$6),0) -> 400 | G7: =ROUNDUP(Empoissonnement!C7*N(Aliments!$J$7),0) -> 0 | H7: =ROUNDUP(Empoissonnement!C7*N(Aliments!$J$8),0) -> 0 | I7: =ROUNDUP(Empoissonnement!C7*N(Aliments!$J$9),0) -> 0 | J7: =SUM(D7:I7) -> 608 | K7: =D7*N(Aliments!$C$4)+E7*N(Aliments!$C$5)+F7*N(Aliments!$C$6)+G7*N(Aliments!$C$7)+H7*N(Aliments!$C$8)+I7*N(Aliments!$C$9) -> 9120 | L7: =(D7*N(Aliments!$D$4)+E7*N(Aliments!$D$5)+F7*N(Aliments!$D$6)+G7*N(Aliments!$D$7)+H7*N(Aliments!$D$8)+I7*N(Aliments!$D$9))*(1-Empoissonnement!$G7) -> 9533440 | N7: =(D7*N(Aliments!$D$4)*N(Aliments!$F$4)+E7*N(Aliments!$D$5)*N(Aliments!$F$5)+F7*N(Aliments!$D$6)*N(Aliments!$F$6)+G7*N(Aliments!$D$7)*N(Aliments!$F$7)+H7*N(Aliments!$D$8)*N(Aliments!$F$8)+I7*N(Aliments!$D$9)*N(Aliments!$F$9))*(1-Empoissonnement!$G7) -> 1368864 | O7: =(D7*N(Aliments!$D$4)*N(Aliments!$G$4)+E7*N(Aliments!$D$5)*N(Aliments!$G$5)+F7*N(Aliments!$D$6)*N(Aliments!$G$6)+G7*N(Aliments!$D$7)*N(Aliments!$G$7)+H7*N(Aliments!$D$8)*N(Aliments!$G$8)+I7*N(Aliments!$D$9)*N(Aliments!$G$9))*(1-Empoissonnement!$G7) -> 4518976 | P7: =(D7*N(Aliments!$D$4)*N(Aliments!$H$4)+E7*N(Aliments!$D$5)*N(Aliments!$H$5)+F7*N(Aliments!$D$6)*N(Aliments!$H$6)+G7*N(Aliments!$D$7)*N(Aliments!$H$7)+H7*N(Aliments!$D$8)*N(Aliments!$H$8)+I7*N(Aliments!$D$9)*N(Aliments!$H$9))*(1-Empoissonnement!$G7) -> 3645600 | Q7: =D7*N(Aliments!$C$4)*N(Aliments!$F$4)+E7*N(Aliments!$C$5)*N(Aliments!$F$5)+F7*N(Aliments!$C$6)*N(Aliments!$F$6)+G7*N(Aliments!$C$7)*N(Aliments!$F$7)+H7*N(Aliments!$C$8)*N(Aliments!$F$8)+I7*N(Aliments!$C$9)*N(Aliments!$F$9) -> 1200 | R7: =D7*N(Aliments!$C$4)*N(Aliments!$G$4)+E7*N(Aliments!$C$5)*N(Aliments!$G$5)+F7*N(Aliments!$C$6)*N(Aliments!$G$6)+G7*N(Aliments!$C$7)*N(Aliments!$G$7)+H7*N(Aliments!$C$8)*N(Aliments!$G$8)+I7*N(Aliments!$C$9)*N(Aliments!$G$9) -> 4320 | S7: =D7*N(Aliments!$C$4)*N(Aliments!$H$4)+E7*N(Aliments!$C$5)*N(Aliments!$H$5)+F7*N(Aliments!$C$6)*N(Aliments!$H$6)+G7*N(Aliments!$C$7)*N(Aliments!$H$7)+H7*N(Aliments!$C$8)*N(Aliments!$H$8)+I7*N(Aliments!$C$9)*N(Aliments!$H$9) -> 3600 | T7: =IFERROR(Q7/INDEX('Besoins aliments'!$H$5:$H$25,MATCH(Empoissonnement!$B7,'Besoins aliments'!$A$5:$A$25,0))*INDEX(Dépenses!$B$31:$V$31,MATCH(Empoissonnement!$B7,Dépenses!$B$3:$V$3,0)),0) -> 204918.03 | U7: =IFERROR(R7/INDEX('Besoins aliments'!$H$5:$H$25,MATCH(EDATE(Empoissonnement!$B7,1),'Besoins aliments'!$A$5:$A$25,0))*INDEX(Dépenses!$B$31:$V$31,MATCH(EDATE(Empoissonnement!$B7,1),Dépenses!$B$3:$V$3,0)),0) -> 621401.27 | V7: =IFERROR(S7/INDEX('Besoins aliments'!$H$5:$H$25,MATCH(EDATE(Empoissonnement!$B7,2),'Besoins aliments'!$A$5:$A$25,0))*INDEX(Dépenses!$B$31:$V$31,MATCH(EDATE(Empoissonnement!$B7,2),Dépenses!$B$3:$V$3,0)),0) -> 461666.67 | W7: =T7+U7+V7 -> 1287986
A8: =Empoissonnement!A8 -> V5 | B8: =Empoissonnement!B8 -> 46357 | C8: =Empoissonnement!C8 -> 10 | D8: =ROUNDUP(Empoissonnement!C8*N(Aliments!$J$4),0) -> 80 | E8: =ROUNDUP(Empoissonnement!C8*N(Aliments!$J$5),0) -> 180 | F8: =ROUNDUP(Empoissonnement!C8*N(Aliments!$J$6),0) -> 500 | G8: =ROUNDUP(Empoissonnement!C8*N(Aliments!$J$7),0) -> 0 | H8: =ROUNDUP(Empoissonnement!C8*N(Aliments!$J$8),0) -> 0 | I8: =ROUNDUP(Empoissonnement!C8*N(Aliments!$J$9),0) -> 0 | J8: =SUM(D8:I8) -> 760 | K8: =D8*N(Aliments!$C$4)+E8*N(Aliments!$C$5)+F8*N(Aliments!$C$6)+G8*N(Aliments!$C$7)+H8*N(Aliments!$C$8)+I8*N(Aliments!$C$9) -> 11400 | L8: =(D8*N(Aliments!$D$4)+E8*N(Aliments!$D$5)+F8*N(Aliments!$D$6)+G8*N(Aliments!$D$7)+H8*N(Aliments!$D$8)+I8*N(Aliments!$D$9))*(1-Empoissonnement!$G8) -> 11673600 | N8: =(D8*N(Aliments!$D$4)*N(Aliments!$F$4)+E8*N(Aliments!$D$5)*N(Aliments!$F$5)+F8*N(Aliments!$D$6)*N(Aliments!$F$6)+G8*N(Aliments!$D$7)*N(Aliments!$F$7)+H8*N(Aliments!$D$8)*N(Aliments!$F$8)+I8*N(Aliments!$D$9)*N(Aliments!$F$9))*(1-Empoissonnement!$G8) -> 1676160 | O8: =(D8*N(Aliments!$D$4)*N(Aliments!$G$4)+E8*N(Aliments!$D$5)*N(Aliments!$G$5)+F8*N(Aliments!$D$6)*N(Aliments!$G$6)+G8*N(Aliments!$D$7)*N(Aliments!$G$7)+H8*N(Aliments!$D$8)*N(Aliments!$G$8)+I8*N(Aliments!$D$9)*N(Aliments!$G$9))*(1-Empoissonnement!$G8) -> 5533440 | P8: =(D8*N(Aliments!$D$4)*N(Aliments!$H$4)+E8*N(Aliments!$D$5)*N(Aliments!$H$5)+F8*N(Aliments!$D$6)*N(Aliments!$H$6)+G8*N(Aliments!$D$7)*N(Aliments!$H$7)+H8*N(Aliments!$D$8)*N(Aliments!$H$8)+I8*N(Aliments!$D$9)*N(Aliments!$H$9))*(1-Empoissonnement!$G8) -> 4464000 | Q8: =D8*N(Aliments!$C$4)*N(Aliments!$F$4)+E8*N(Aliments!$C$5)*N(Aliments!$F$5)+F8*N(Aliments!$C$6)*N(Aliments!$F$6)+G8*N(Aliments!$C$7)*N(Aliments!$F$7)+H8*N(Aliments!$C$8)*N(Aliments!$F$8)+I8*N(Aliments!$C$9)*N(Aliments!$F$9) -> 1500 | R8: =D8*N(Aliments!$C$4)*N(Aliments!$G$4)+E8*N(Aliments!$C$5)*N(Aliments!$G$5)+F8*N(Aliments!$C$6)*N(Aliments!$G$6)+G8*N(Aliments!$C$7)*N(Aliments!$G$7)+H8*N(Aliments!$C$8)*N(Aliments!$G$8)+I8*N(Aliments!$C$9)*N(Aliments!$G$9) -> 5400 | S8: =D8*N(Aliments!$C$4)*N(Aliments!$H$4)+E8*N(Aliments!$C$5)*N(Aliments!$H$5)+F8*N(Aliments!$C$6)*N(Aliments!$H$6)+G8*N(Aliments!$C$7)*N(Aliments!$H$7)+H8*N(Aliments!$C$8)*N(Aliments!$H$8)+I8*N(Aliments!$C$9)*N(Aliments!$H$9) -> 4500 | T8: =IFERROR(Q8/INDEX('Besoins aliments'!$H$5:$H$25,MATCH(Empoissonnement!$B8,'Besoins aliments'!$A$5:$A$25,0))*INDEX(Dépenses!$B$31:$V$31,MATCH(Empoissonnement!$B8,Dépenses!$B$3:$V$3,0)),0) -> 215764.33 | U8: =IFERROR(R8/INDEX('Besoins aliments'!$H$5:$H$25,MATCH(EDATE(Empoissonnement!$B8,1),'Besoins aliments'!$A$5:$A$25,0))*INDEX(Dépenses!$B$31:$V$31,MATCH(EDATE(Empoissonnement!$B8,1),Dépenses!$B$3:$V$3,0)),0) -> 692500 | V8: =IFERROR(S8/INDEX('Besoins aliments'!$H$5:$H$25,MATCH(EDATE(Empoissonnement!$B8,2),'Besoins aliments'!$A$5:$A$25,0))*INDEX(Dépenses!$B$31:$V$31,MATCH(EDATE(Empoissonnement!$B8,2),Dépenses!$B$3:$V$3,0)),0) -> 500000 | W8: =T8+U8+V8 -> 1408264.3
A9: =Empoissonnement!A9 -> V6 | B9: =Empoissonnement!B9 -> 46388 | C9: =Empoissonnement!C9 -> 12 | D9: =ROUNDUP(Empoissonnement!C9*N(Aliments!$J$4),0) -> 96 | E9: =ROUNDUP(Empoissonnement!C9*N(Aliments!$J$5),0) -> 216 | F9: =ROUNDUP(Empoissonnement!C9*N(Aliments!$J$6),0) -> 600 | G9: =ROUNDUP(Empoissonnement!C9*N(Aliments!$J$7),0) -> 0 | H9: =ROUNDUP(Empoissonnement!C9*N(Aliments!$J$8),0) -> 0 | I9: =ROUNDUP(Empoissonnement!C9*N(Aliments!$J$9),0) -> 0 | J9: =SUM(D9:I9) -> 912 | K9: =D9*N(Aliments!$C$4)+E9*N(Aliments!$C$5)+F9*N(Aliments!$C$6)+G9*N(Aliments!$C$7)+H9*N(Aliments!$C$8)+I9*N(Aliments!$C$9) -> 13680 | L9: =(D9*N(Aliments!$D$4)+E9*N(Aliments!$D$5)+F9*N(Aliments!$D$6)+G9*N(Aliments!$D$7)+H9*N(Aliments!$D$8)+I9*N(Aliments!$D$9))*(1-Empoissonnement!$G9) -> 14008320 | N9: =(D9*N(Aliments!$D$4)*N(Aliments!$F$4)+E9*N(Aliments!$D$5)*N(Aliments!$F$5)+F9*N(Aliments!$D$6)*N(Aliments!$F$6)+G9*N(Aliments!$D$7)*N(Aliments!$F$7)+H9*N(Aliments!$D$8)*N(Aliments!$F$8)+I9*N(Aliments!$D$9)*N(Aliments!$F$9))*(1-Empoissonnement!$G9) -> 2011392 | O9: =(D9*N(Aliments!$D$4)*N(Aliments!$G$4)+E9*N(Aliments!$D$5)*N(Aliments!$G$5)+F9*N(Aliments!$D$6)*N(Aliments!$G$6)+G9*N(Aliments!$D$7)*N(Aliments!$G$7)+H9*N(Aliments!$D$8)*N(Aliments!$G$8)+I9*N(Aliments!$D$9)*N(Aliments!$G$9))*(1-Empoissonnement!$G9) -> 6640128 | P9: =(D9*N(Aliments!$D$4)*N(Aliments!$H$4)+E9*N(Aliments!$D$5)*N(Aliments!$H$5)+F9*N(Aliments!$D$6)*N(Aliments!$H$6)+G9*N(Aliments!$D$7)*N(Aliments!$H$7)+H9*N(Aliments!$D$8)*N(Aliments!$H$8)+I9*N(Aliments!$D$9)*N(Aliments!$H$9))*(1-Empoissonnement!$G9) -> 5356800 | Q9: =D9*N(Aliments!$C$4)*N(Aliments!$F$4)+E9*N(Aliments!$C$5)*N(Aliments!$F$5)+F9*N(Aliments!$C$6)*N(Aliments!$F$6)+G9*N(Aliments!$C$7)*N(Aliments!$F$7)+H9*N(Aliments!$C$8)*N(Aliments!$F$8)+I9*N(Aliments!$C$9)*N(Aliments!$F$9) -> 1800 | R9: =D9*N(Aliments!$C$4)*N(Aliments!$G$4)+E9*N(Aliments!$C$5)*N(Aliments!$G$5)+F9*N(Aliments!$C$6)*N(Aliments!$G$6)+G9*N(Aliments!$C$7)*N(Aliments!$G$7)+H9*N(Aliments!$C$8)*N(Aliments!$G$8)+I9*N(Aliments!$C$9)*N(Aliments!$G$9) -> 6480 | S9: =D9*N(Aliments!$C$4)*N(Aliments!$H$4)+E9*N(Aliments!$C$5)*N(Aliments!$H$5)+F9*N(Aliments!$C$6)*N(Aliments!$H$6)+G9*N(Aliments!$C$7)*N(Aliments!$H$7)+H9*N(Aliments!$C$8)*N(Aliments!$H$8)+I9*N(Aliments!$C$9)*N(Aliments!$H$9) -> 5400 | T9: =IFERROR(Q9/INDEX('Besoins aliments'!$H$5:$H$25,MATCH(Empoissonnement!$B9,'Besoins aliments'!$A$5:$A$25,0))*INDEX(Dépenses!$B$31:$V$31,MATCH(Empoissonnement!$B9,Dépenses!$B$3:$V$3,0)),0) -> 230833.33 | U9: =IFERROR(R9/INDEX('Besoins aliments'!$H$5:$H$25,MATCH(EDATE(Empoissonnement!$B9,1),'Besoins aliments'!$A$5:$A$25,0))*INDEX(Dépenses!$B$31:$V$31,MATCH(EDATE(Empoissonnement!$B9,1),Dépenses!$B$3:$V$3,0)),0) -> 720000 | V9: =IFERROR(S9/INDEX('Besoins aliments'!$H$5:$H$25,MATCH(EDATE(Empoissonnement!$B9,2),'Besoins aliments'!$A$5:$A$25,0))*INDEX(Dépenses!$B$31:$V$31,MATCH(EDATE(Empoissonnement!$B9,2),Dépenses!$B$3:$V$3,0)),0) -> 528000 | W9: =T9+U9+V9 -> 1478833.3
A10: =Empoissonnement!A10 -> V7 | B10: =Empoissonnement!B10 -> 46419 | C10: =Empoissonnement!C10 -> 15 | D10: =ROUNDUP(Empoissonnement!C10*N(Aliments!$J$4),0) -> 120 | E10: =ROUNDUP(Empoissonnement!C10*N(Aliments!$J$5),0) -> 270 | F10: =ROUNDUP(Empoissonnement!C10*N(Aliments!$J$6),0) -> 750 | G10: =ROUNDUP(Empoissonnement!C10*N(Aliments!$J$7),0) -> 0 | H10: =ROUNDUP(Empoissonnement!C10*N(Aliments!$J$8),0) -> 0 | I10: =ROUNDUP(Empoissonnement!C10*N(Aliments!$J$9),0) -> 0 | J10: =SUM(D10:I10) -> 1140 | K10: =D10*N(Aliments!$C$4)+E10*N(Aliments!$C$5)+F10*N(Aliments!$C$6)+G10*N(Aliments!$C$7)+H10*N(Aliments!$C$8)+I10*N(Aliments!$C$9) -> 17100 | L10: =(D10*N(Aliments!$D$4)+E10*N(Aliments!$D$5)+F10*N(Aliments!$D$6)+G10*N(Aliments!$D$7)+H10*N(Aliments!$D$8)+I10*N(Aliments!$D$9))*(1-Empoissonnement!$G10) -> 17145600 | N10: =(D10*N(Aliments!$D$4)*N(Aliments!$F$4)+E10*N(Aliments!$D$5)*N(Aliments!$F$5)+F10*N(Aliments!$D$6)*N(Aliments!$F$6)+G10*N(Aliments!$D$7)*N(Aliments!$F$7)+H10*N(Aliments!$D$8)*N(Aliments!$F$8)+I10*N(Aliments!$D$9)*N(Aliments!$F$9))*(1-Empoissonnement!$G10) -> 2461860 | O10: =(D10*N(Aliments!$D$4)*N(Aliments!$G$4)+E10*N(Aliments!$D$5)*N(Aliments!$G$5)+F10*N(Aliments!$D$6)*N(Aliments!$G$6)+G10*N(Aliments!$D$7)*N(Aliments!$G$7)+H10*N(Aliments!$D$8)*N(Aliments!$G$8)+I10*N(Aliments!$D$9)*N(Aliments!$G$9))*(1-Empoissonnement!$G10) -> 8127240 | P10: =(D10*N(Aliments!$D$4)*N(Aliments!$H$4)+E10*N(Aliments!$D$5)*N(Aliments!$H$5)+F10*N(Aliments!$D$6)*N(Aliments!$H$6)+G10*N(Aliments!$D$7)*N(Aliments!$H$7)+H10*N(Aliments!$D$8)*N(Aliments!$H$8)+I10*N(Aliments!$D$9)*N(Aliments!$H$9))*(1-Empoissonnement!$G10) -> 6556500 | Q10: =D10*N(Aliments!$C$4)*N(Aliments!$F$4)+E10*N(Aliments!$C$5)*N(Aliments!$F$5)+F10*N(Aliments!$C$6)*N(Aliments!$F$6)+G10*N(Aliments!$C$7)*N(Aliments!$F$7)+H10*N(Aliments!$C$8)*N(Aliments!$F$8)+I10*N(Aliments!$C$9)*N(Aliments!$F$9) -> 2250 | R10: =D10*N(Aliments!$C$4)*N(Aliments!$G$4)+E10*N(Aliments!$C$5)*N(Aliments!$G$5)+F10*N(Aliments!$C$6)*N(Aliments!$G$6)+G10*N(Aliments!$C$7)*N(Aliments!$G$7)+H10*N(Aliments!$C$8)*N(Aliments!$G$8)+I10*N(Aliments!$C$9)*N(Aliments!$G$9) -> 8100 | S10: =D10*N(Aliments!$C$4)*N(Aliments!$H$4)+E10*N(Aliments!$C$5)*N(Aliments!$H$5)+F10*N(Aliments!$C$6)*N(Aliments!$H$6)+G10*N(Aliments!$C$7)*N(Aliments!$H$7)+H10*N(Aliments!$C$8)*N(Aliments!$H$8)+I10*N(Aliments!$C$9)*N(Aliments!$H$9) -> 6750 | T10: =IFERROR(Q10/INDEX('Besoins aliments'!$H$5:$H$25,MATCH(Empoissonnement!$B10,'Besoins aliments'!$A$5:$A$25,0))*INDEX(Dépenses!$B$31:$V$31,MATCH(Empoissonnement!$B10,Dépenses!$B$3:$V$3,0)),0) -> 250000 | U10: =IFERROR(R10/INDEX('Besoins aliments'!$H$5:$H$25,MATCH(EDATE(Empoissonnement!$B10,1),'Besoins aliments'!$A$5:$A$25,0))*INDEX(Dépenses!$B$31:$V$31,MATCH(EDATE(Empoissonnement!$B10,1),Dépenses!$B$3:$V$3,0)),0) -> 792000 | V10: =IFERROR(S10/INDEX('Besoins aliments'!$H$5:$H$25,MATCH(EDATE(Empoissonnement!$B10,2),'Besoins aliments'!$A$5:$A$25,0))*INDEX(Dépenses!$B$31:$V$31,MATCH(EDATE(Empoissonnement!$B10,2),Dépenses!$B$3:$V$3,0)),0) -> 633552.63 | W10: =T10+U10+V10 -> 1675552.6
A11: =Empoissonnement!A11 -> V8 | B11: =Empoissonnement!B11 -> 46447 | C11: =Empoissonnement!C11 -> 15 | D11: =ROUNDUP(Empoissonnement!C11*N(Aliments!$J$4),0) -> 120 | E11: =ROUNDUP(Empoissonnement!C11*N(Aliments!$J$5),0) -> 270 | F11: =ROUNDUP(Empoissonnement!C11*N(Aliments!$J$6),0) -> 750 | G11: =ROUNDUP(Empoissonnement!C11*N(Aliments!$J$7),0) -> 0 | H11: =ROUNDUP(Empoissonnement!C11*N(Aliments!$J$8),0) -> 0 | I11: =ROUNDUP(Empoissonnement!C11*N(Aliments!$J$9),0) -> 0 | J11: =SUM(D11:I11) -> 1140 | K11: =D11*N(Aliments!$C$4)+E11*N(Aliments!$C$5)+F11*N(Aliments!$C$6)+G11*N(Aliments!$C$7)+H11*N(Aliments!$C$8)+I11*N(Aliments!$C$9) -> 17100 | L11: =(D11*N(Aliments!$D$4)+E11*N(Aliments!$D$5)+F11*N(Aliments!$D$6)+G11*N(Aliments!$D$7)+H11*N(Aliments!$D$8)+I11*N(Aliments!$D$9))*(1-Empoissonnement!$G11) -> 17145600 | N11: =(D11*N(Aliments!$D$4)*N(Aliments!$F$4)+E11*N(Aliments!$D$5)*N(Aliments!$F$5)+F11*N(Aliments!$D$6)*N(Aliments!$F$6)+G11*N(Aliments!$D$7)*N(Aliments!$F$7)+H11*N(Aliments!$D$8)*N(Aliments!$F$8)+I11*N(Aliments!$D$9)*N(Aliments!$F$9))*(1-Empoissonnement!$G11) -> 2461860 | O11: =(D11*N(Aliments!$D$4)*N(Aliments!$G$4)+E11*N(Aliments!$D$5)*N(Aliments!$G$5)+F11*N(Aliments!$D$6)*N(Aliments!$G$6)+G11*N(Aliments!$D$7)*N(Aliments!$G$7)+H11*N(Aliments!$D$8)*N(Aliments!$G$8)+I11*N(Aliments!$D$9)*N(Aliments!$G$9))*(1-Empoissonnement!$G11) -> 8127240 | P11: =(D11*N(Aliments!$D$4)*N(Aliments!$H$4)+E11*N(Aliments!$D$5)*N(Aliments!$H$5)+F11*N(Aliments!$D$6)*N(Aliments!$H$6)+G11*N(Aliments!$D$7)*N(Aliments!$H$7)+H11*N(Aliments!$D$8)*N(Aliments!$H$8)+I11*N(Aliments!$D$9)*N(Aliments!$H$9))*(1-Empoissonnement!$G11) -> 6556500 | Q11: =D11*N(Aliments!$C$4)*N(Aliments!$F$4)+E11*N(Aliments!$C$5)*N(Aliments!$F$5)+F11*N(Aliments!$C$6)*N(Aliments!$F$6)+G11*N(Aliments!$C$7)*N(Aliments!$F$7)+H11*N(Aliments!$C$8)*N(Aliments!$F$8)+I11*N(Aliments!$C$9)*N(Aliments!$F$9) -> 2250 | R11: =D11*N(Aliments!$C$4)*N(Aliments!$G$4)+E11*N(Aliments!$C$5)*N(Aliments!$G$5)+F11*N(Aliments!$C$6)*N(Aliments!$G$6)+G11*N(Aliments!$C$7)*N(Aliments!$G$7)+H11*N(Aliments!$C$8)*N(Aliments!$G$8)+I11*N(Aliments!$C$9)*N(Aliments!$G$9) -> 8100 | S11: =D11*N(Aliments!$C$4)*N(Aliments!$H$4)+E11*N(Aliments!$C$5)*N(Aliments!$H$5)+F11*N(Aliments!$C$6)*N(Aliments!$H$6)+G11*N(Aliments!$C$7)*N(Aliments!$H$7)+H11*N(Aliments!$C$8)*N(Aliments!$H$8)+I11*N(Aliments!$C$9)*N(Aliments!$H$9) -> 6750 | T11: =IFERROR(Q11/INDEX('Besoins aliments'!$H$5:$H$25,MATCH(Empoissonnement!$B11,'Besoins aliments'!$A$5:$A$25,0))*INDEX(Dépenses!$B$31:$V$31,MATCH(Empoissonnement!$B11,Dépenses!$B$3:$V$3,0)),0) -> 220000 | U11: =IFERROR(R11/INDEX('Besoins aliments'!$H$5:$H$25,MATCH(EDATE(Empoissonnement!$B11,1),'Besoins aliments'!$A$5:$A$25,0))*INDEX(Dépenses!$B$31:$V$31,MATCH(EDATE(Empoissonnement!$B11,1),Dépenses!$B$3:$V$3,0)),0) -> 760263.16 | V11: =IFERROR(S11/INDEX('Besoins aliments'!$H$5:$H$25,MATCH(EDATE(Empoissonnement!$B11,2),'Besoins aliments'!$A$5:$A$25,0))*INDEX(Dépenses!$B$31:$V$31,MATCH(EDATE(Empoissonnement!$B11,2),Dépenses!$B$3:$V$3,0)),0) -> 633552.63 | W11: =T11+U11+V11 -> 1613815.8
A12: =Empoissonnement!A12 -> V9 | B12: =Empoissonnement!B12 -> 46478 | C12: =Empoissonnement!C12 -> 15 | D12: =ROUNDUP(Empoissonnement!C12*N(Aliments!$J$4),0) -> 120 | E12: =ROUNDUP(Empoissonnement!C12*N(Aliments!$J$5),0) -> 270 | F12: =ROUNDUP(Empoissonnement!C12*N(Aliments!$J$6),0) -> 750 | G12: =ROUNDUP(Empoissonnement!C12*N(Aliments!$J$7),0) -> 0 | H12: =ROUNDUP(Empoissonnement!C12*N(Aliments!$J$8),0) -> 0 | I12: =ROUNDUP(Empoissonnement!C12*N(Aliments!$J$9),0) -> 0 | J12: =SUM(D12:I12) -> 1140 | K12: =D12*N(Aliments!$C$4)+E12*N(Aliments!$C$5)+F12*N(Aliments!$C$6)+G12*N(Aliments!$C$7)+H12*N(Aliments!$C$8)+I12*N(Aliments!$C$9) -> 17100 | L12: =(D12*N(Aliments!$D$4)+E12*N(Aliments!$D$5)+F12*N(Aliments!$D$6)+G12*N(Aliments!$D$7)+H12*N(Aliments!$D$8)+I12*N(Aliments!$D$9))*(1-Empoissonnement!$G12) -> 17145600 | N12: =(D12*N(Aliments!$D$4)*N(Aliments!$F$4)+E12*N(Aliments!$D$5)*N(Aliments!$F$5)+F12*N(Aliments!$D$6)*N(Aliments!$F$6)+G12*N(Aliments!$D$7)*N(Aliments!$F$7)+H12*N(Aliments!$D$8)*N(Aliments!$F$8)+I12*N(Aliments!$D$9)*N(Aliments!$F$9))*(1-Empoissonnement!$G12) -> 2461860 | O12: =(D12*N(Aliments!$D$4)*N(Aliments!$G$4)+E12*N(Aliments!$D$5)*N(Aliments!$G$5)+F12*N(Aliments!$D$6)*N(Aliments!$G$6)+G12*N(Aliments!$D$7)*N(Aliments!$G$7)+H12*N(Aliments!$D$8)*N(Aliments!$G$8)+I12*N(Aliments!$D$9)*N(Aliments!$G$9))*(1-Empoissonnement!$G12) -> 8127240 | P12: =(D12*N(Aliments!$D$4)*N(Aliments!$H$4)+E12*N(Aliments!$D$5)*N(Aliments!$H$5)+F12*N(Aliments!$D$6)*N(Aliments!$H$6)+G12*N(Aliments!$D$7)*N(Aliments!$H$7)+H12*N(Aliments!$D$8)*N(Aliments!$H$8)+I12*N(Aliments!$D$9)*N(Aliments!$H$9))*(1-Empoissonnement!$G12) -> 6556500 | Q12: =D12*N(Aliments!$C$4)*N(Aliments!$F$4)+E12*N(Aliments!$C$5)*N(Aliments!$F$5)+F12*N(Aliments!$C$6)*N(Aliments!$F$6)+G12*N(Aliments!$C$7)*N(Aliments!$F$7)+H12*N(Aliments!$C$8)*N(Aliments!$F$8)+I12*N(Aliments!$C$9)*N(Aliments!$F$9) -> 2250 | R12: =D12*N(Aliments!$C$4)*N(Aliments!$G$4)+E12*N(Aliments!$C$5)*N(Aliments!$G$5)+F12*N(Aliments!$C$6)*N(Aliments!$G$6)+G12*N(Aliments!$C$7)*N(Aliments!$G$7)+H12*N(Aliments!$C$8)*N(Aliments!$G$8)+I12*N(Aliments!$C$9)*N(Aliments!$G$9) -> 8100 | S12: =D12*N(Aliments!$C$4)*N(Aliments!$H$4)+E12*N(Aliments!$C$5)*N(Aliments!$H$5)+F12*N(Aliments!$C$6)*N(Aliments!$H$6)+G12*N(Aliments!$C$7)*N(Aliments!$H$7)+H12*N(Aliments!$C$8)*N(Aliments!$H$8)+I12*N(Aliments!$C$9)*N(Aliments!$H$9) -> 6750 | T12: =IFERROR(Q12/INDEX('Besoins aliments'!$H$5:$H$25,MATCH(Empoissonnement!$B12,'Besoins aliments'!$A$5:$A$25,0))*INDEX(Dépenses!$B$31:$V$31,MATCH(Empoissonnement!$B12,Dépenses!$B$3:$V$3,0)),0) -> 211184.21 | U12: =IFERROR(R12/INDEX('Besoins aliments'!$H$5:$H$25,MATCH(EDATE(Empoissonnement!$B12,1),'Besoins aliments'!$A$5:$A$25,0))*INDEX(Dépenses!$B$31:$V$31,MATCH(EDATE(Empoissonnement!$B12,1),Dépenses!$B$3:$V$3,0)),0) -> 760263.16 | V12: =IFERROR(S12/INDEX('Besoins aliments'!$H$5:$H$25,MATCH(EDATE(Empoissonnement!$B12,2),'Besoins aliments'!$A$5:$A$25,0))*INDEX(Dépenses!$B$31:$V$31,MATCH(EDATE(Empoissonnement!$B12,2),Dépenses!$B$3:$V$3,0)),0) -> 633552.63 | W12: =T12+U12+V12 -> 1605000
A13: =Empoissonnement!A13 -> V10 | B13: =Empoissonnement!B13 -> 46508 | C13: =Empoissonnement!C13 -> 15 | D13: =ROUNDUP(Empoissonnement!C13*N(Aliments!$J$4),0) -> 120 | E13: =ROUNDUP(Empoissonnement!C13*N(Aliments!$J$5),0) -> 270 | F13: =ROUNDUP(Empoissonnement!C13*N(Aliments!$J$6),0) -> 750 | G13: =ROUNDUP(Empoissonnement!C13*N(Aliments!$J$7),0) -> 0 | H13: =ROUNDUP(Empoissonnement!C13*N(Aliments!$J$8),0) -> 0 | I13: =ROUNDUP(Empoissonnement!C13*N(Aliments!$J$9),0) -> 0 | J13: =SUM(D13:I13) -> 1140 | K13: =D13*N(Aliments!$C$4)+E13*N(Aliments!$C$5)+F13*N(Aliments!$C$6)+G13*N(Aliments!$C$7)+H13*N(Aliments!$C$8)+I13*N(Aliments!$C$9) -> 17100 | L13: =(D13*N(Aliments!$D$4)+E13*N(Aliments!$D$5)+F13*N(Aliments!$D$6)+G13*N(Aliments!$D$7)+H13*N(Aliments!$D$8)+I13*N(Aliments!$D$9))*(1-Empoissonnement!$G13) -> 17145600 | N13: =(D13*N(Aliments!$D$4)*N(Aliments!$F$4)+E13*N(Aliments!$D$5)*N(Aliments!$F$5)+F13*N(Aliments!$D$6)*N(Aliments!$F$6)+G13*N(Aliments!$D$7)*N(Aliments!$F$7)+H13*N(Aliments!$D$8)*N(Aliments!$F$8)+I13*N(Aliments!$D$9)*N(Aliments!$F$9))*(1-Empoissonnement!$G13) -> 2461860 | O13: =(D13*N(Aliments!$D$4)*N(Aliments!$G$4)+E13*N(Aliments!$D$5)*N(Aliments!$G$5)+F13*N(Aliments!$D$6)*N(Aliments!$G$6)+G13*N(Aliments!$D$7)*N(Aliments!$G$7)+H13*N(Aliments!$D$8)*N(Aliments!$G$8)+I13*N(Aliments!$D$9)*N(Aliments!$G$9))*(1-Empoissonnement!$G13) -> 8127240 | P13: =(D13*N(Aliments!$D$4)*N(Aliments!$H$4)+E13*N(Aliments!$D$5)*N(Aliments!$H$5)+F13*N(Aliments!$D$6)*N(Aliments!$H$6)+G13*N(Aliments!$D$7)*N(Aliments!$H$7)+H13*N(Aliments!$D$8)*N(Aliments!$H$8)+I13*N(Aliments!$D$9)*N(Aliments!$H$9))*(1-Empoissonnement!$G13) -> 6556500 | Q13: =D13*N(Aliments!$C$4)*N(Aliments!$F$4)+E13*N(Aliments!$C$5)*N(Aliments!$F$5)+F13*N(Aliments!$C$6)*N(Aliments!$F$6)+G13*N(Aliments!$C$7)*N(Aliments!$F$7)+H13*N(Aliments!$C$8)*N(Aliments!$F$8)+I13*N(Aliments!$C$9)*N(Aliments!$F$9) -> 2250 | R13: =D13*N(Aliments!$C$4)*N(Aliments!$G$4)+E13*N(Aliments!$C$5)*N(Aliments!$G$5)+F13*N(Aliments!$C$6)*N(Aliments!$G$6)+G13*N(Aliments!$C$7)*N(Aliments!$G$7)+H13*N(Aliments!$C$8)*N(Aliments!$G$8)+I13*N(Aliments!$C$9)*N(Aliments!$G$9) -> 8100 | S13: =D13*N(Aliments!$C$4)*N(Aliments!$H$4)+E13*N(Aliments!$C$5)*N(Aliments!$H$5)+F13*N(Aliments!$C$6)*N(Aliments!$H$6)+G13*N(Aliments!$C$7)*N(Aliments!$H$7)+H13*N(Aliments!$C$8)*N(Aliments!$H$8)+I13*N(Aliments!$C$9)*N(Aliments!$H$9) -> 6750 | T13: =IFERROR(Q13/INDEX('Besoins aliments'!$H$5:$H$25,MATCH(Empoissonnement!$B13,'Besoins aliments'!$A$5:$A$25,0))*INDEX(Dépenses!$B$31:$V$31,MATCH(Empoissonnement!$B13,Dépenses!$B$3:$V$3,0)),0) -> 211184.21 | U13: =IFERROR(R13/INDEX('Besoins aliments'!$H$5:$H$25,MATCH(EDATE(Empoissonnement!$B13,1),'Besoins aliments'!$A$5:$A$25,0))*INDEX(Dépenses!$B$31:$V$31,MATCH(EDATE(Empoissonnement!$B13,1),Dépenses!$B$3:$V$3,0)),0) -> 760263.16 | V13: =IFERROR(S13/INDEX('Besoins aliments'!$H$5:$H$25,MATCH(EDATE(Empoissonnement!$B13,2),'Besoins aliments'!$A$5:$A$25,0))*INDEX(Dépenses!$B$31:$V$31,MATCH(EDATE(Empoissonnement!$B13,2),Dépenses!$B$3:$V$3,0)),0) -> 633552.63 | W13: =T13+U13+V13 -> 1605000
A14: =Empoissonnement!A14 -> V11 | B14: =Empoissonnement!B14 -> 46539 | C14: =Empoissonnement!C14 -> 15 | D14: =ROUNDUP(Empoissonnement!C14*N(Aliments!$J$4),0) -> 120 | E14: =ROUNDUP(Empoissonnement!C14*N(Aliments!$J$5),0) -> 270 | F14: =ROUNDUP(Empoissonnement!C14*N(Aliments!$J$6),0) -> 750 | G14: =ROUNDUP(Empoissonnement!C14*N(Aliments!$J$7),0) -> 0 | H14: =ROUNDUP(Empoissonnement!C14*N(Aliments!$J$8),0) -> 0 | I14: =ROUNDUP(Empoissonnement!C14*N(Aliments!$J$9),0) -> 0 | J14: =SUM(D14:I14) -> 1140 | K14: =D14*N(Aliments!$C$4)+E14*N(Aliments!$C$5)+F14*N(Aliments!$C$6)+G14*N(Aliments!$C$7)+H14*N(Aliments!$C$8)+I14*N(Aliments!$C$9) -> 17100 | L14: =(D14*N(Aliments!$D$4)+E14*N(Aliments!$D$5)+F14*N(Aliments!$D$6)+G14*N(Aliments!$D$7)+H14*N(Aliments!$D$8)+I14*N(Aliments!$D$9))*(1-Empoissonnement!$G14) -> 17145600 | N14: =(D14*N(Aliments!$D$4)*N(Aliments!$F$4)+E14*N(Aliments!$D$5)*N(Aliments!$F$5)+F14*N(Aliments!$D$6)*N(Aliments!$F$6)+G14*N(Aliments!$D$7)*N(Aliments!$F$7)+H14*N(Aliments!$D$8)*N(Aliments!$F$8)+I14*N(Aliments!$D$9)*N(Aliments!$F$9))*(1-Empoissonnement!$G14) -> 2461860 | O14: =(D14*N(Aliments!$D$4)*N(Aliments!$G$4)+E14*N(Aliments!$D$5)*N(Aliments!$G$5)+F14*N(Aliments!$D$6)*N(Aliments!$G$6)+G14*N(Aliments!$D$7)*N(Aliments!$G$7)+H14*N(Aliments!$D$8)*N(Aliments!$G$8)+I14*N(Aliments!$D$9)*N(Aliments!$G$9))*(1-Empoissonnement!$G14) -> 8127240 | P14: =(D14*N(Aliments!$D$4)*N(Aliments!$H$4)+E14*N(Aliments!$D$5)*N(Aliments!$H$5)+F14*N(Aliments!$D$6)*N(Aliments!$H$6)+G14*N(Aliments!$D$7)*N(Aliments!$H$7)+H14*N(Aliments!$D$8)*N(Aliments!$H$8)+I14*N(Aliments!$D$9)*N(Aliments!$H$9))*(1-Empoissonnement!$G14) -> 6556500 | Q14: =D14*N(Aliments!$C$4)*N(Aliments!$F$4)+E14*N(Aliments!$C$5)*N(Aliments!$F$5)+F14*N(Aliments!$C$6)*N(Aliments!$F$6)+G14*N(Aliments!$C$7)*N(Aliments!$F$7)+H14*N(Aliments!$C$8)*N(Aliments!$F$8)+I14*N(Aliments!$C$9)*N(Aliments!$F$9) -> 2250 | R14: =D14*N(Aliments!$C$4)*N(Aliments!$G$4)+E14*N(Aliments!$C$5)*N(Aliments!$G$5)+F14*N(Aliments!$C$6)*N(Aliments!$G$6)+G14*N(Aliments!$C$7)*N(Aliments!$G$7)+H14*N(Aliments!$C$8)*N(Aliments!$G$8)+I14*N(Aliments!$C$9)*N(Aliments!$G$9) -> 8100 | S14: =D14*N(Aliments!$C$4)*N(Aliments!$H$4)+E14*N(Aliments!$C$5)*N(Aliments!$H$5)+F14*N(Aliments!$C$6)*N(Aliments!$H$6)+G14*N(Aliments!$C$7)*N(Aliments!$H$7)+H14*N(Aliments!$C$8)*N(Aliments!$H$8)+I14*N(Aliments!$C$9)*N(Aliments!$H$9) -> 6750 | T14: =IFERROR(Q14/INDEX('Besoins aliments'!$H$5:$H$25,MATCH(Empoissonnement!$B14,'Besoins aliments'!$A$5:$A$25,0))*INDEX(Dépenses!$B$31:$V$31,MATCH(Empoissonnement!$B14,Dépenses!$B$3:$V$3,0)),0) -> 211184.21 | U14: =IFERROR(R14/INDEX('Besoins aliments'!$H$5:$H$25,MATCH(EDATE(Empoissonnement!$B14,1),'Besoins aliments'!$A$5:$A$25,0))*INDEX(Dépenses!$B$31:$V$31,MATCH(EDATE(Empoissonnement!$B14,1),Dépenses!$B$3:$V$3,0)),0) -> 760263.16 | V14: =IFERROR(S14/INDEX('Besoins aliments'!$H$5:$H$25,MATCH(EDATE(Empoissonnement!$B14,2),'Besoins aliments'!$A$5:$A$25,0))*INDEX(Dépenses!$B$31:$V$31,MATCH(EDATE(Empoissonnement!$B14,2),Dépenses!$B$3:$V$3,0)),0) -> 633552.63 | W14: =T14+U14+V14 -> 1605000
A15: =Empoissonnement!A15 -> V12 | B15: =Empoissonnement!B15 -> 46569 | C15: =Empoissonnement!C15 -> 15 | D15: =ROUNDUP(Empoissonnement!C15*N(Aliments!$J$4),0) -> 120 | E15: =ROUNDUP(Empoissonnement!C15*N(Aliments!$J$5),0) -> 270 | F15: =ROUNDUP(Empoissonnement!C15*N(Aliments!$J$6),0) -> 750 | G15: =ROUNDUP(Empoissonnement!C15*N(Aliments!$J$7),0) -> 0 | H15: =ROUNDUP(Empoissonnement!C15*N(Aliments!$J$8),0) -> 0 | I15: =ROUNDUP(Empoissonnement!C15*N(Aliments!$J$9),0) -> 0 | J15: =SUM(D15:I15) -> 1140 | K15: =D15*N(Aliments!$C$4)+E15*N(Aliments!$C$5)+F15*N(Aliments!$C$6)+G15*N(Aliments!$C$7)+H15*N(Aliments!$C$8)+I15*N(Aliments!$C$9) -> 17100 | L15: =(D15*N(Aliments!$D$4)+E15*N(Aliments!$D$5)+F15*N(Aliments!$D$6)+G15*N(Aliments!$D$7)+H15*N(Aliments!$D$8)+I15*N(Aliments!$D$9))*(1-Empoissonnement!$G15) -> 17145600 | N15: =(D15*N(Aliments!$D$4)*N(Aliments!$F$4)+E15*N(Aliments!$D$5)*N(Aliments!$F$5)+F15*N(Aliments!$D$6)*N(Aliments!$F$6)+G15*N(Aliments!$D$7)*N(Aliments!$F$7)+H15*N(Aliments!$D$8)*N(Aliments!$F$8)+I15*N(Aliments!$D$9)*N(Aliments!$F$9))*(1-Empoissonnement!$G15) -> 2461860 | O15: =(D15*N(Aliments!$D$4)*N(Aliments!$G$4)+E15*N(Aliments!$D$5)*N(Aliments!$G$5)+F15*N(Aliments!$D$6)*N(Aliments!$G$6)+G15*N(Aliments!$D$7)*N(Aliments!$G$7)+H15*N(Aliments!$D$8)*N(Aliments!$G$8)+I15*N(Aliments!$D$9)*N(Aliments!$G$9))*(1-Empoissonnement!$G15) -> 8127240 | P15: =(D15*N(Aliments!$D$4)*N(Aliments!$H$4)+E15*N(Aliments!$D$5)*N(Aliments!$H$5)+F15*N(Aliments!$D$6)*N(Aliments!$H$6)+G15*N(Aliments!$D$7)*N(Aliments!$H$7)+H15*N(Aliments!$D$8)*N(Aliments!$H$8)+I15*N(Aliments!$D$9)*N(Aliments!$H$9))*(1-Empoissonnement!$G15) -> 6556500 | Q15: =D15*N(Aliments!$C$4)*N(Aliments!$F$4)+E15*N(Aliments!$C$5)*N(Aliments!$F$5)+F15*N(Aliments!$C$6)*N(Aliments!$F$6)+G15*N(Aliments!$C$7)*N(Aliments!$F$7)+H15*N(Aliments!$C$8)*N(Aliments!$F$8)+I15*N(Aliments!$C$9)*N(Aliments!$F$9) -> 2250 | R15: =D15*N(Aliments!$C$4)*N(Aliments!$G$4)+E15*N(Aliments!$C$5)*N(Aliments!$G$5)+F15*N(Aliments!$C$6)*N(Aliments!$G$6)+G15*N(Aliments!$C$7)*N(Aliments!$G$7)+H15*N(Aliments!$C$8)*N(Aliments!$G$8)+I15*N(Aliments!$C$9)*N(Aliments!$G$9) -> 8100 | S15: =D15*N(Aliments!$C$4)*N(Aliments!$H$4)+E15*N(Aliments!$C$5)*N(Aliments!$H$5)+F15*N(Aliments!$C$6)*N(Aliments!$H$6)+G15*N(Aliments!$C$7)*N(Aliments!$H$7)+H15*N(Aliments!$C$8)*N(Aliments!$H$8)+I15*N(Aliments!$C$9)*N(Aliments!$H$9) -> 6750 | T15: =IFERROR(Q15/INDEX('Besoins aliments'!$H$5:$H$25,MATCH(Empoissonnement!$B15,'Besoins aliments'!$A$5:$A$25,0))*INDEX(Dépenses!$B$31:$V$31,MATCH(Empoissonnement!$B15,Dépenses!$B$3:$V$3,0)),0) -> 211184.21 | U15: =IFERROR(R15/INDEX('Besoins aliments'!$H$5:$H$25,MATCH(EDATE(Empoissonnement!$B15,1),'Besoins aliments'!$A$5:$A$25,0))*INDEX(Dépenses!$B$31:$V$31,MATCH(EDATE(Empoissonnement!$B15,1),Dépenses!$B$3:$V$3,0)),0) -> 760263.16 | V15: =IFERROR(S15/INDEX('Besoins aliments'!$H$5:$H$25,MATCH(EDATE(Empoissonnement!$B15,2),'Besoins aliments'!$A$5:$A$25,0))*INDEX(Dépenses!$B$31:$V$31,MATCH(EDATE(Empoissonnement!$B15,2),Dépenses!$B$3:$V$3,0)),0) -> 633552.63 | W15: =T15+U15+V15 -> 1605000
... A22: =Empoissonnement!A22 -> V19 | B22: =Empoissonnement!B22 -> 46784 | C22: =Empoissonnement!C22 -> 15 | D22: =ROUNDUP(Empoissonnement!C22*N(Aliments!$J$4),0) -> 120 | E22: =ROUNDUP(Empoissonnement!C22*N(Aliments!$J$5),0) -> 270 | F22: =ROUNDUP(Empoissonnement!C22*N(Aliments!$J$6),0) -> 750 | G22: =ROUNDUP(Empoissonnement!C22*N(Aliments!$J$7),0) -> 0 | H22: =ROUNDUP(Empoissonnement!C22*N(Aliments!$J$8),0) -> 0 | I22: =ROUNDUP(Empoissonnement!C22*N(Aliments!$J$9),0) -> 0 | J22: =SUM(D22:I22) -> 1140 | K22: =D22*N(Aliments!$C$4)+E22*N(Aliments!$C$5)+F22*N(Aliments!$C$6)+G22*N(Aliments!$C$7)+H22*N(Aliments!$C$8)+I22*N(Aliments!$C$9) -> 17100 | L22: =(D22*N(Aliments!$D$4)+E22*N(Aliments!$D$5)+F22*N(Aliments!$D$6)+G22*N(Aliments!$D$7)+H22*N(Aliments!$D$8)+I22*N(Aliments!$D$9))*(1-Empoissonnement!$G22) -> 17145600 | N22: =(D22*N(Aliments!$D$4)*N(Aliments!$F$4)+E22*N(Aliments!$D$5)*N(Aliments!$F$5)+F22*N(Aliments!$D$6)*N(Aliments!$F$6)+G22*N(Aliments!$D$7)*N(Aliments!$F$7)+H22*N(Aliments!$D$8)*N(Aliments!$F$8)+I22*N(Aliments!$D$9)*N(Aliments!$F$9))*(1-Empoissonnement!$G22) -> 2461860 | O22: =(D22*N(Aliments!$D$4)*N(Aliments!$G$4)+E22*N(Aliments!$D$5)*N(Aliments!$G$5)+F22*N(Aliments!$D$6)*N(Aliments!$G$6)+G22*N(Aliments!$D$7)*N(Aliments!$G$7)+H22*N(Aliments!$D$8)*N(Aliments!$G$8)+I22*N(Aliments!$D$9)*N(Aliments!$G$9))*(1-Empoissonnement!$G22) -> 8127240 | P22: =(D22*N(Aliments!$D$4)*N(Aliments!$H$4)+E22*N(Aliments!$D$5)*N(Aliments!$H$5)+F22*N(Aliments!$D$6)*N(Aliments!$H$6)+G22*N(Aliments!$D$7)*N(Aliments!$H$7)+H22*N(Aliments!$D$8)*N(Aliments!$H$8)+I22*N(Aliments!$D$9)*N(Aliments!$H$9))*(1-Empoissonnement!$G22) -> 6556500 | Q22: =D22*N(Aliments!$C$4)*N(Aliments!$F$4)+E22*N(Aliments!$C$5)*N(Aliments!$F$5)+F22*N(Aliments!$C$6)*N(Aliments!$F$6)+G22*N(Aliments!$C$7)*N(Aliments!$F$7)+H22*N(Aliments!$C$8)*N(Aliments!$F$8)+I22*N(Aliments!$C$9)*N(Aliments!$F$9) -> 2250 | R22: =D22*N(Aliments!$C$4)*N(Aliments!$G$4)+E22*N(Aliments!$C$5)*N(Aliments!$G$5)+F22*N(Aliments!$C$6)*N(Aliments!$G$6)+G22*N(Aliments!$C$7)*N(Aliments!$G$7)+H22*N(Aliments!$C$8)*N(Aliments!$G$8)+I22*N(Aliments!$C$9)*N(Aliments!$G$9) -> 8100 | S22: =D22*N(Aliments!$C$4)*N(Aliments!$H$4)+E22*N(Aliments!$C$5)*N(Aliments!$H$5)+F22*N(Aliments!$C$6)*N(Aliments!$H$6)+G22*N(Aliments!$C$7)*N(Aliments!$H$7)+H22*N(Aliments!$C$8)*N(Aliments!$H$8)+I22*N(Aliments!$C$9)*N(Aliments!$H$9) -> 6750 | T22: =IFERROR(Q22/INDEX('Besoins aliments'!$H$5:$H$25,MATCH(Empoissonnement!$B22,'Besoins aliments'!$A$5:$A$25,0))*INDEX(Dépenses!$B$31:$V$31,MATCH(Empoissonnement!$B22,Dépenses!$B$3:$V$3,0)),0) -> 211184.21 | U22: =IFERROR(R22/INDEX('Besoins aliments'!$H$5:$H$25,MATCH(EDATE(Empoissonnement!$B22,1),'Besoins aliments'!$A$5:$A$25,0))*INDEX(Dépenses!$B$31:$V$31,MATCH(EDATE(Empoissonnement!$B22,1),Dépenses!$B$3:$V$3,0)),0) -> 810000 | V22: =IFERROR(S22/INDEX('Besoins aliments'!$H$5:$H$25,MATCH(EDATE(Empoissonnement!$B22,2),'Besoins aliments'!$A$5:$A$25,0))*INDEX(Dépenses!$B$31:$V$31,MATCH(EDATE(Empoissonnement!$B22,2),Dépenses!$B$3:$V$3,0)),0) -> 1350000 | W22: =T22+U22+V22 -> 2371184.2
A23: TOTAL | D23: =SUM(D4:D22) -> 1928 | E23: =SUM(E4:E22) -> 4338 | F23: =SUM(F4:F22) -> 12050 | G23: =SUM(G4:G22) -> 0 | H23: =SUM(H4:H22) -> 0 | I23: =SUM(I4:I22) -> 0 | J23: =SUM(J4:J22) -> 18316 | K23: =SUM(K4:K22) -> 274740 | L23: =SUM(L4:L22) -> 277369600 | N23: =SUM(N4:N22) -> 39826260 | O23: =SUM(O4:O22) -> 131476840 | P23: =SUM(P4:P22) -> 106066500

Sheet Besoins aliments
A1: BESOINS EN ALIMENTS PAR MOIS ET PAR GRANULOMÉTRIE
A2: Détail par granulomètrie, calculé à partir de VOTRE saisie de la feuille « Aliment par vague », répartie entre granulométries selon la feuille Aliments. Le coût d'achat est au prix catalogue (avant remise fournisseur) ; la dépense réelle, remise déduite, est calculée dans les Prévisions.
B3: Quantités à prévoir (kg) | I3: Sacs à commander (nb)
A4: Mois | B4: =Aliments!$A$4 -> 2 mm | C4: =Aliments!$A$5 -> 3 mm | D4: =Aliments!$A$6 -> 4 mm | E4: =Aliments!$A$7 -> 0 | F4: =Aliments!$A$8 -> 0 | G4: =Aliments!$A$9 -> 0 | H4: TOTAL (kg) | I4: =Aliments!$A$4 -> 2 mm | J4: =Aliments!$A$5 -> 3 mm | K4: =Aliments!$A$6 -> 4 mm | L4: =Aliments!$A$7 -> 0 | M4: =Aliments!$A$8 -> 0 | N4: =Aliments!$A$9 -> 0 | O4: Coût d'achat du mois (FCFA)
